Workbook

Sheet Financial Projections
H1: Page 13 | J1: A. STATEMENT OF REVENUES AND EXPENSES
J2: Current Tax Year | K2: Proposed | L2: Proposed | M2: Proposed | N2: Actuals
J3: 45658 | K3: Present to | L3: 46023 | M3: 46388 | N3: 45292
J4: To present | K4: 46022 | L4: 46387 | M4: 46752 | N4: 45657
H5: Revenue
B6: Revenue for 1023 online | G6: 40000 | H6: Direct Contributions Revenue
A7: 1 | B7: =J7+J8 -> 20000 | C7: =#REF!+#REF! -> #REF! | D7: =K7+K8 -> 380000 | E7: =L7+L8 -> 750000 | F7: 1 | G7: 40100 | H7: Individual/Small business contributions | J7: 20000 | K7: 0 | L7: 50000 | M7: 100000
A8: 2 | B8: =J11 -> 0 | C8: =#REF! -> #REF! | D8: =K11 -> 0 | E8: =L11 -> 0 | F8: 1 | G8: 40200 | H8: Corporate Contributions | J8: 0 | K8: 380000 | L8: 700000 | M8: 1000000
A9: 3 | B9: =J13 -> 0 | C9: =#REF! -> #REF! | D9: =K13 -> 2650 | E9: =L13 -> 9800 | H9: Subtotal Line 1 | J9: =SUM(J7:J8) -> 20000 | K9: =SUM(K7:K8) -> 380000 | L9: =SUM(L7:L8) -> 750000 | M9: =SUM(M7:M8) -> 1100000
G10: 46000 | H10: Membership Dues | J10: 0 | K10: 0 | L10: 0 | M10: 0
F11: 2 | G11: 46100 | H11: Membership Dues | I11: 2 | J11: 0 | K11: 0 | L11: 0 | M11: 0
G12: 48000 | H12: Investment Revenue
F13: 3 | G13: 48100 | H13: Interest-- Savings/Short-term Investments | I13: 3 | J13: 0 | K13: 2650 | L13: 9800 | M13: 14700
F14: 4 | G14: 49500 | H14: Unrelated Business Income | I14: 4 | J14: 0 | K14: 0 | L14: 0 | M14: 0
A15: 4 | B15: =J14 -> 0 | C15: =#REF! -> #REF! | D15: =K14 -> 0 | E15: =L14 -> 0 | G15: 41000 | H15: Donated Goods & Services Revenue | I15: 7
A16: 9 | B16: =J18+J19+J20+J21+J22+J25+J26+J27+J28+J29+J32+J33 -> 0 | C16: =#REF!+#REF!+#REF!+#REF!+#REF!+#REF!+#REF!+#REF!+#REF!+#REF!+#REF!+#REF! -> #REF! | D16: =K18+K19+K20+K21+K22+K25+K26+K27+K28+K29+K32+K33 -> 0 | E16: =L18+L19+L20+L21+L22+L25+L26+L27+L28+L29+L32+L33 -> 125000 | F16: 7 | G16: 41100 | H16: Gifts In-Kind | J16: 0 | K16: 0 | L16: 0 | M16: 0
F17: 9 | G17: 45000 | H17: Program Service Revenues
G18: 45100 | H18: Program #1 Revenue (Sway for students and general public) | J18: 0 | K18: 0 | L18: 100000 | M18: 350000
G19: 45200 | H19: Program #2 Revenue (faculty training workshops) | J19: 0 | K19: 0 | L19: 25000 | M19: 50000
G20: 45300 | H20: Program #3 Revenue (empirical research studies) | J20: 0 | K20: 0 | L20: 0 | M20: 0
G21: 45400 | H21: Program #4 Revenue | J21: 0 | K21: 0 | L21: 0 | M21: 0
G22: 45500 | H22: Program #5 Revenue | J22: 0 | K22: 0 | L22: 0 | M22: 0
G24: 47000 | H24: Fundraising Event Revenues | J24: 0 | K24: 0 | L24: 0 | M24: 0
F25: 9 | G25: 47100 | H25: Fundraising Event #1 Gross Revenue | J25: 0 | K25: 0 | L25: 0 | M25: 0
F26: 9 | G26: 47200 | H26: Fundraising Event #2 Gross Revenue | J26: 0 | K26: 0 | L26: 0 | M26: 0
F27: 9 | G27: 47300 | H27: Fundraising Event #3 Gross Revenue | J27: 0 | K27: 0 | L27: 0 | M27: 0
F28: 9 | G28: 47400 | H28: Fundraising Event #4 Gross Revenue | J28: 0 | K28: 0 | L28: 0 | M28: 0
F29: 9 | G29: 47500 | H29: Fundraising Event #5 Gross Revenue | J29: 0 | K29: 0 | L29: 0 | M29: 0
G31: 49000 | H31: Other Revenues | J31: 0 | K31: 0 | L31: 0 | M31: 0
F32: 9 | G32: 49100 | H32: Non-Inventory Sales-- Gross | J32: 0 | K32: 0 | L32: 0 | M32: 0
F33: 9 | G33: 49200 | H33: Inventory Sales-- Gross | J33: 0 | K33: 0 | L33: 0 | M33: 0
H34: Subtotal Line 9 | J34: =SUM(J18:J33) -> 0 | K34: =SUM(K18:K33) -> 0 | L34: =SUM(L18:L33) -> 125000 | M34: =SUM(M18:M33) -> 400000
F35: 13 | H35: Total Income/Revenue | J35: =J34+J16+J14+J13+J11+J9 -> 20000 | K35: =K34+K16+K14+K13+K11+K9 -> 382650 | L35: =L34+L16+L14+L13+L11+L9 -> 884800 | M35: =M34+M16+M14+M13+M11+M9 -> 1514700
B36: Expenses for 1023 online
H37: Expenses
G39: 70000 | H39: Fundraising Expenses
F40: 14 | G40: 71000 | H40: Fundraising Event #1 Cash Prizes | J40: 0 | K40: 0 | L40: 0 | M40: 0
F41: 14 | G41: 71100 | H41: Fundraising Event #1 Noncash prizes | J41: 0 | K41: 0 | L41: 0 | M41: 0
F42: 14 | G42: 71200 | H42: Fundraising Event #1 Rent/Facility Costs | J42: 0 | K42: 0 | L42: 0 | M42: 0
F43: 14 | G43: 71300 | H43: Fundraising Event #1 Food & Beverage | J43: 0 | K43: 0 | L43: 0 | M43: 0
...

Sheet Salary Breakdown
A1: Salary Breakdown - totals should transfer to Chart of Accounts lines 51100 & 51200 respectively | C1: Current Tax Year 1/1/2025 - Present | D1: Proposed Present - 12/31/2025 | E1: Proposed 1/1/2026 - 12/31/2026 | F1: Proposed 1/1/2027 - 12/31/2027 | G1: Actuals 1/1/2024 - 12/31/2024
A4: Line 17 | B4: Officers, Directors/Trustees, Key Employees Salaries (51100)
B5: Simon Cullen, President/Scientist | C5: 0 | D5: 0 | E5: 0 | F5: 150000 | G5: 0
B6: Nicholas DiBella, Treasurer/Secretary/Scientist | C6: 0 | D6: 15000 | E6: 110000 | F6: 110000
B7: Director of Technical Programs
B8: Research Scientist | C8: 0 | D8: 0 | E8: 100000 | F8: 100000
B9: Research Scientist | C9: 0 | D9: 0 | E9: 100000 | F9: 100000
A11: 51100 | B11: Total carries to Line 51100 of Chart of Accounts | C11: =SUM(C5:C10) -> 0 | D11: =SUM(D5:D10) -> 15000 | E11: =SUM(E5:E10) -> 310000 | F11: =SUM(F5:F10) -> 460000 | G11: =SUM(G5:G10) -> 0
A13: Line 18 | B13: Salaries & Wages- Other (51200)
B15: Job Title /Name of Person Hired, (if known)
B16: Job Title /Name of Person Hired, (if known)
B17: Job Title /Name of Person Hired, (if known)
A19: 51200 | B19: Total carries to Line 51200 of Chart of Accounts | C19: =SUM(C14:C18) -> 0 | D19: =SUM(D14:D18) -> 0 | E19: =SUM(E14:E18) -> 0 | F19: =SUM(F14:F18) -> 0 | G19: =SUM(G14:G18) -> 0
D147: =SUM(D43:D146) -> 0 | E147: =SUM(E43:E146) -> 0 | F147: =SUM(F43:F146) -> 0 | G147: =SUM(G43:G146) -> 0

Sheet Financial Actuals
H1: Page 13 | J1: A. STATEMENT OF REVENUES AND EXPENSES
J2: Actuals | K2: Actuals | L2: Actuals | M2: Actuals
J3: 43831 | K3: 44197 | L3: 44562 | M3: 44927
J4: 44196 | K4: 44561 | L4: 44926 | M4: 45291
H5: Revenue
B6: Revenue for 1023 online | G6: 40000 | H6: Direct Contributions Revenue
A7: 1 | B7: =J7+J8 -> 0 | C7: =#REF!+#REF! -> #REF! | D7: =K7+K8 -> 0 | E7: =L7+L8 -> 0 | F7: 1 | G7: 40100 | H7: Individual/Small business contributions
A8: 2 | B8: =J11 | C8: =#REF! -> #REF! | D8: =K11 | E8: =L11 | F8: 1 | G8: 40200 | H8: Corporate Contributions
A9: 3 | B9: =J13 | C9: =#REF! -> #REF! | D9: =K13 | E9: =L13 | H9: Subtotal Line 1 | J9: =SUM(J7:J8) -> 0 | K9: =SUM(K7:K8) -> 0 | L9: =SUM(L7:L8) -> 0 | M9: =SUM(M7:M8) -> 0
G10: 46000 | H10: Membership Dues
F11: 2 | G11: 46100 | H11: Membership Dues
G12: 48000 | H12: Investment Revenue
F13: 3 | G13: 48100 | H13: Interest-- Savings/Short-term Investments
F14: 4 | G14: 49500 | H14: Unrelated Business Income
A15: 4 | B15: =J14 | C15: =#REF! -> #REF! | D15: =K14 | E15: =L14 | G15: 41000 | H15: Donated Goods & Services Revenue
A16: 9 | B16: =J18+J19+J20+J21+J22+J25+J26+J27+J28+J29+J32+J33 -> 0 | C16: =#REF!+#REF!+#REF!+#REF!+#REF!+#REF!+#REF!+#REF!+#REF!+#REF!+#REF!+#REF! -> #REF! | D16: =K18+K19+K20+K21+K22+K25+K26+K27+K28+K29+K32+K33 -> 0 | E16: =L18+L19+L20+L21+L22+L25+L26+L27+L28+L29+L32+L33 -> 0 | F16: 7 | G16: 41100 | H16: Gifts In-Kind
F17: 9 | G17: 45000 | H17: Program Service Revenues
G18: 45100 | H18: Program #1 Revenue
G19: 45200 | H19: Program #2 Revenue
G20: 45300 | H20: Program #3 Revenue
G21: 45400 | H21: Program #4 Revenue
G22: 45500 | H22: Program #5 Revenue
G24: 47000 | H24: Fundraising Event Revenues
F25: 9 | G25: 47100 | H25: Fundraising Event #1 Gross Revenue
F26: 9 | G26: 47200 | H26: Fundraising Event #2 Gross Revenue
F27: 9 | G27: 47300 | H27: Fundraising Event #3 Gross Revenue
F28: 9 | G28: 47400 | H28: Fundraising Event #4 Gross Revenue
F29: 9 | G29: 47500 | H29: Fundraising Event #5 Gross Revenue
G31: 49000 | H31: Other Revenues
F32: 9 | G32: 49100 | H32: Non-Inventory Sales-- Gross
F33: 9 | G33: 49200 | H33: Inventory Sales-- Gross
H34: Subtotal Line 9 | J34: =SUM(J18:J33) -> 0 | K34: =SUM(K18:K33) -> 0 | L34: =SUM(L18:L33) -> 0 | M34: =SUM(M18:M33) -> 0
F35: 13 | H35: Total Income/Revenue | J35: =J34+J16+J14+J13+J11+J9 -> 0 | K35: =K34+K16+K14+K13+K11+K9 -> 0 | L35: =L34+L16+L14+L13+L11+L9 -> 0 | M35: =M34+M16+M14+M13+M11+M9 -> 0
B36: Expenses for 1023 online
H37: Expenses
G39: 70000 | H39: Fundraising Expenses
F40: 14 | G40: 71000 | H40: Fundraising Event #1 Cash Prizes
F41: 14 | G41: 71100 | H41: Fundraising Event #1 Noncash prizes
F42: 14 | G42: 71200 | H42: Fundraising Event #1 Rent/Facility Costs
F43: 14 | G43: 71300 | H43: Fundraising Event #1 Food & Beverage
...

Sheet Program Expense Itemize List
A1: Expense Item | B1: Estimated Cost
